Workbook

Sheet % Consulta pré anestésica
A1: ANO | C1: 2025
A2: TAXA DE PROCEDIMENTOS ELETIVOS COM CONSULTA PRÉ-ANESTÉSICA AMBULATORIAL | C2: =C4/C5 -> 0.79517191 | D2: =D4/D5 -> 0.79330007 | E2: =E4/E5 -> 0.75690236 | F2: =F4/F5 -> 0.84649123 | G2: =G4/G5 -> 0.85654513 | H2: =H4/H5 -> 0.96018277 | I2: =I4/I5 -> 0.95281996 | J2: =J4/J5 -> 0.97834758 | K2: =K4/K5 -> 0.97022198 | O2: =MEDIAN(C2:N2) -> 0.85654513
A3: MÊS | C3: Janeiro | D3: Fevereiro | E3: Março | F3: Abril | G3: Maio | H3: Junho | I3: Julho | J3: Agosto | K3: Setembro | L3: Outubro | M3: Novembro | N3: Dezembro | O3: MÉDIA ANUAL
A4: Nº de pacientes submetidos a procedimentos eletivos sob anestesia/sedação com realização de consulta pré-anestésica ambulatorial. | C4: 1087 | D4: 1113 | E4: 1124 | F4: 1351 | G4: 1433 | H4: 1471 | I4: 1757 | J4: 1717 | K4: 1792 | L4: 0 | M4: 0 | N4: 0 | O4: =MEDIAN(C4:N4) -> 1237.5
A5: Nº de pacientes submetidos a procedimentos eletivos sob anestesia/sedação. | C5: 1367 | D5: 1403 | E5: 1485 | F5: 1596 | G5: 1673 | H5: 1532 | I5: 1844 | J5: 1755 | K5: 1847 | L5: 0 | M5: 0 | N5: 0 | O5: =MEDIAN(C5:N5) -> 1508.5
A6: Meta | C6: > 95%
A7: MÊS | B7: Análise Critica | D7: Plan (Planejar) | G7: Do (Executar/Fazer) | J7: Check (Verificar/Checar) | M7: Act (Agir/Ajustar/Padronizar)
A8: 1º Trimestre (Jan–Fev–Mar) | B8: O indicador manteve desempenho significativamente abaixo da meta (>95%), com resultados de 79%, 78% e 74%, representando deterioração progressiva do processo. Entre janeiro e março, o total de procedimentos eletivos sob anestesia/sedação aumentou 7% (de 1.400 para 1.501), mas o número de consultas pré-anestésicas ambulatoriais não acompanhou essa expansão, crescendo apenas 1% (de 1.099 para 1.109). O Centro Cirúrgico concentrou a maior parte das falhas — grande volume de avaliações realizadas no dia da cirurgia e ausência de registro eletrônico formal. O Serviço de Imagem, embora com média de 636 exames anestésicos por mês, apresentava apenas 50% de cobertura de consulta prévia (média de 308 consultas). As falhas de comunicação entre equipes e inconsistências nos consentimentos anestésicos impactaram a confiabilidade do dado. | D8: Reestruturar o fluxo de consulta pré-anestésica ambulatorial com definição de critérios obrigatórios de agendamento e responsabilidades entre anestesia, cirurgia e marcação cirúrgica. Criar rotina mínima de 48h para avaliação prévia e padronizar os registros em instrumento único. Iniciar a implantação de sistema informatizado (Axreg) para rastreabilidade e controle. | G8: Ações pontuais de sensibilização das equipes e reuniões operacionais com anestesistas e enfermagem para revisar o fluxo de marcação. As auditorias clínicas foram iniciadas, porém com baixa abrangência e sem padronização de indicadores. O processo de agendamento permaneceu majoritariamente manual. | J8: O desempenho manteve-se abaixo da meta, sem evolução significativa. Houve subnotificação e falhas de rastreabilidade, com predominância de registros manuais e ausência de integração entre setores. As falhas mais críticas envolveram consultas não sinalizadas e inconsistências em termos de consentimento. | M8: Iniciar revisão estrutural do processo com definição clara de responsabilidades e implantação piloto do Axreg. Criar protocolo institucional de consulta pré-anestésica obrigatória para todos os procedimentos eletivos e monitoramento sistemático por auditoria clínica.
A11: 2º Trimestre (Abr–Mai–Jun) | B11: O segundo trimestre apresentou tendência de recuperação — o indicador evoluiu de 84% em abril para 93% em junho, o melhor resultado do semestre. O número de procedimentos eletivos sob anestesia aumentou de 1.601 para 1.550 (-3%), enquanto as consultas prévias cresceram 7% (de 1.351 para 1.446), sinalizando melhor aderência ao protocolo. O Centro Cirúrgico manteve crescimento na proporção de pacientes avaliados antes do procedimento (802 em abril para 788 em junho). O Serviço de Imagem apresentou ganho expressivo: 672 exames anestésicos em abril e 612 em junho, com aumento das consultas prévias de 482 para 600. As auditorias mostraram redução nas falhas documentais e maior comunicação entre setores, embora a meta de 95% ainda não tenha sido alcançada. | D11: Consolidar a padronização dos fluxos de avaliação pré-anestésica, com foco em adesão integral das equipes e rastreabilidade eletrônica via Axreg. Definir rotina mensal de auditorias e reforçar a comunicação intersetorial. Estabelecer metas intermediárias de 90% e 93% até o atingimento da meta de 95%. | G11: Houve maior engajamento operacional: reuniões de alinhamento com equipes, capacitações sobre o protocolo e início do uso formal do Axreg em parte dos serviços. As auditorias clínicas passaram a acompanhar a execução do fluxo. | J11: O desempenho de 93% em junho confirmou o impacto das ações implementadas, com redução das falhas de registro e avanço na rastreabilidade. Contudo, persistiram falhas de sinalização no sistema e casos isolados de pareceres realizados no centro cirúrgico. | M11: Reforçar o uso obrigatório do Axreg em todos os serviços (centro cirúrgico, obstétrico e imagem). Formalizar POP institucional de pré-anestesia e intensificar as auditorias cruzadas mensais, além de ampliar os treinamentos periódicos.
A14: MÊS | B14: Análise Critica | D14: Plan (Planejar) | G14: Do (Executar/Fazer) | J14: Check (Verificar/Checar) | M14: Act (Agir/Ajustar/Padronizar)
A15: JULHO | B15: O indicador apresentou desempenho de 93%, evidenciando consolidação das melhorias implementadas no semestre anterior e fortalecimento da cultura de segurança perioperatória. Observou-se progressiva adesão das equipes médicas e de enfermagem ao protocolo de consulta pré-anestésica ambulatorial, com destaque para o aumento expressivo dos procedimentos eletivos com pré-consulta (1.741 em julho contra 1.446 em junho) e melhoria da rastreabilidade documental. Houve também ampliação da obrigatoriedade da consulta para exames de imagem sob anestesia, que registraram 804 procedimentos anestésicos, representando avanço na integração entre os setores. Entretanto, persistiram falhas no uso do sistema Axreg, com registros incompletos e consultas realizadas no mesmo dia do procedimento, além da ausência de padronização plena nos lançamentos, o que impactou a mensuração do indicador. | D15: Garantir que 95% dos pacientes submetidos a procedimentos eletivos sob anestesia/sedação realizem consulta pré-anestésica ambulatorial, assegurando o alcance da meta ≥95%. Implementar ações voltadas à sensibilização dos cirurgiões sobre o fluxo de agendamento e prazos mínimos, promover a adoção obrigatória do sistema Axreg como ferramenta oficial de registro e fortalecer a integração entre marcação cirúrgica, anestesia e enfermagem por meio de reuniões de bate-mapa. | G15: Foram executadas ações para fortalecer o cumprimento do protocolo, com ênfase na padronização dos fluxos e na qualificação das equipes. Reforçou-se a obrigatoriedade da consulta pré-anestésica também para exames de imagem, endoscopias, colonoscopias sob anestesia, ampliando a cobertura do processo. As equipes foram sensibilizadas quanto ao correto registro no Axreg, consolidado como ferramenta oficial de rastreabilidade. A integração intersetorial foi intensificada no bate-mapa, permitindo melhor planejamento e redução de falhas. | J15: O resultado de 93% manteve evolução consistente em relação aos meses anteriores, demonstrando maior adesão das equipes, porém ainda abaixo da meta. As auditorias evidenciaram avanços na organização do fluxo e na execução das consultas, mas persistiram falhas operacionais, especialmente na utilização do Axreg e na subcaptura de dados. A confiabilidade do indicador ainda depende de ajustes na padronização e na integração do sistema com o Hospital Unimed Chapecó. | M15: Adotar medidas corretivas e de padronização para consolidar o processo e alcançar a meta. Tornar obrigatório o registro das consultas no Axreg, com bloqueio de agendamento sem o devido lançamento. Revisar e uniformizar o fluxo documental, fortalecer auditorias cruzadas mensais e implementar capacitação contínua das equipes médicas, de enfermagem e administrativas, consolidando a padronização institucional.
A16: AGOSTO | B16: O indicador apresentou desempenho satisfatório em 97%, superando a meta institucional e refletindo o impacto positivo das ações corretivas adotadas nos meses anteriores. O resultado demonstra avanço consolidado na adesão das equipes médicas e de enfermagem as ações voltadas ao protocolo, embora ainda existam margens de melhoria na estabilidade e padronização dos registros. Observou-se ampliação do uso do Axreg, com redução de inconsistências documentais. No serviço de imagem, 767 procedimentos anestésicos foram realizados, todos com avaliação ou consulta prévia, reforçando a consolidação do fluxo. Entretanto, o processo ainda requer ajustes na coleta e integração dos dados, garantindo sustentabilidade e confiabilidade das informações. | D16: Garantir a realização da consulta pré-anestésica ambulatorial para todos dos pacientes submetidos a procedimentos eletivos e exames de imagem sob anestesia, mantendo o desempenho acima da meta institucional (≥95%). Consolidar o uso obrigatório do sistema Axreg como ferramenta única de registro, revisar periodicamente os fluxos intersetoriais e reforçar a educação permanente das equipes quanto à rastreabilidade e à importância do planejamento pré-operatório | G16: Foram intensificadas as auditorias clínicas e acompanhamentos operacionais para monitorar a adesão ao protocolo. As equipes de anestesia e enfermagem atuaram de forma integrada no bate-mapa, assegurando alinhamento entre agendamentos e consultas. O uso do Axreg foi amplamente incorporado, reduzindo falhas de documentação e garantindo a obrigatoriedade da consulta também para exames de imagem sob anestesia ou sedação. | J16: O resultado de 97% representa superação da meta e comprova a efetividade das ações implementadas. Houve uma significativa redução de inconsistências e a adesão consolidada ao uso do Axreg. A integração entre marcação cirúrgica e anestesia mostrou-se estável e eficaz. | M16: Será reavaliado ainda a busca dos dados do indicador junto a unimed chapecó. O Axreg será mantido como sistema oficial e obrigatório de registro das avaliações pré-anestésicas, abrangendo cirurgias e exames de imagem. Permanecem as auditorias cruzadas mensais e o acompanhamento intersetorial, além da educação continuada das equipes para garantir sustentabilidade, qualidade assistencial e cultura de conformidade.
A17: SETEMBRO | B17: O indicador manteve-se dentro da meta institucional, atingindo 95% em setembro, demonstrando estabilidade do desempenho e sustentação dos avanços obtidos nos meses anteriores, embora com leve queda em relação a agosto (97%). A variação está associada ao aumento do volume assistencial, com 1021 pacientes atendidos no centro cirúrgico, sendo 896 procedimentos eletivos e 854 anestesias realizadas. O serviço de imagem também registrou 4710 atendimentos, com 830 procedimentos anestésicos, todos com consulta prévia. Apesar da boa adesão, ainda foram observadas inconsistências no registro das avaliações pré anestesicas no Axreg, especialmente nas realizadas previamente antes do procedimento cirúrgico. | D17: Manter o indicador acima da meta de 95%, consolidando a prática da consulta pré-anestésica ambulatorial para todos os pacientes eletivos e exames de imagem sob anestesia. Reforçar a padronização dos registros no Axreg e o controle das avaliações pré anestesicas através da utilização do axReg. Garantir uniformidade na coleta e análise de dados e promover ações educativas contínuas voltadas à sustentabilidade do processo. | G17: Foram mantidas as ações operacionais e de auditoria, com reforço no acompanhamento das agendas de consulta e anestesia. As equipes atuaram de forma integrada no bate-mapa, ajustando fluxos diante do aumento de volume. O uso do Axreg foi ampliado e tornou-se obrigatória a consulta ou avaliação pré anestesica também para exames de imagem. | J17: O resultado de 95% confirma o cumprimento da meta e a manutenção do processo em patamar estável, apesar do crescimento da demanda. Observou-se boa adesão e melhoria contínua na rastreabilidade, mas ainda persistem falhas pontuais na padronização e integração sistêmica dos dados. | M17: Implementar padronização definitiva do fluxo de registro e coleta de dados no Axreg, com automação entre o sistema de agendamento cirúrgico e o de imagem. Fortalecer auditorias cruzadas intersetoriais e instituir checagem eletrônica obrigatória antes do agendamento. Manter capacitações mensais com foco em consolidação da governança clínica e sustentabilidade dos resultados.
A18: MÊS | B18: Análise Critica | D18: Plan (Planejar) | G18: Do (Executar/Fazer) | J18: Check (Verificar/Checar) | M18: Act (Agir/Ajustar/Padronizar)
A19: OUTUBRO
A20: NOVEMBRO
A21: DEZEMBRO

Sheet % Incidencia de dor aguda
A1: INCIDÊNCIA DE DOR AGUDA NO PERÍODO INTRAOPERATÓRIO ATÉ A ALTA ANESTÉSICA | C1: 2025
C2: =C4/C5 -> 0.050951087 | D2: =D4/D5 -> 0.043648208 | E2: =E4/E5 -> 0.040443575 | F2: =F4/F5 -> 0.034525277 | G2: =G4/G5 -> 0.059738643 | H2: =H4/H5 -> 0.033333333 | I2: =I4/I5 -> 0.035934868 | J2: =J4/J5 -> 0.03372093 | K2: =K4/K5 -> 0.036752606 | O2: =+MEDIAN(C2:N2) -> 0.036752606
A3: MÊS | C3: Janeiro | D3: Fevereiro | E3: Março | F3: Abril | G3: Maio | H3: Junho | I3: Julho | J3: Agosto | K3: Setembro | L3: Outubro | M3: Novembro | N3: Dezembro | O3: MÉDIA ANUAL
A4: Nº de pacientes que apresentaram dor aguda no período intraoperatório até a alta anestésica da SRPA ou transferência para UTI. | C4: 75 | D4: 67 | E4: 62 | F4: 56 | G4: 96 | H4: 51 | I4: 64 | J4: 58 | K4: 67 | L4: 0 | M4: 0 | N4: 0 | O4: =+MEDIAN(C4:N4) -> 60
A5: Nº de pacientes submetidos a procedimentos sob anestesia/sedação. | C5: 1472 | D5: 1535 | E5: 1533 | F5: 1622 | G5: 1607 | H5: 1530 | I5: 1781 | J5: 1720 | K5: 1823 | L5: 0 | M5: 0 | N5: 0 | O5: =+MEDIAN(C5:N5) -> 1534
A6: META | C6: <5%
A7: MÊS | B7: Análise Critica | D7: Plan (Planejar) | G7: Do (Executar/Fazer) | J7: Check (Verificar/Checar) | M7: Act (Agir/Ajustar/Padronizar)
A8: JANEIRO | B8: O mês apresentou incidência de 5% de pacientes com dor intensa ou insuportável e de difícil controle, situando-se no limite da meta estabelecida (<5%). Foram 75 casos de dor intensa entre 1.472 pacientes anestesiados, evidenciando fragilidade no manejo analgésico intra e pós-operatório imediato. Apesar de 793 pacientes (54%) não relatarem dor e 121 (8%) apresentarem dor leve a moderada, o número de casos graves ainda indica inconsistência na efetividade da analgesia preventiva. As auditorias apontaram ausência de padronização de condutas analgésicas, uso irregular de escalas de dor e planos anestésicos genéricos, sem individualização conforme o tipo cirúrgico. Além disso, a falha de comunicação entre o centro cirúrgico e a SRPA contribuiu para o subtratamento analgésico no pós-operatório. | D8: Diante do resultado de 5% em janeiro e da manutenção acima do nível ideal, foi identificada a necessidade de estruturar um plano de ação voltado à uniformização do manejo analgésico, tanto intraoperatório quanto na SRPA. As auditorias apontaram ausência de protocolo institucional, uso irregular das escalas de dor, planos anestésicos pouco individualizados e falhas na comunicação entre anestesia e enfermagem. O objetivo definido foi reduzir a incidência de dor aguda abaixo de 4%, com melhor registro e avaliação sistemática da dor. | G8: Neste trimestre, as ações foram pontuais e não sistematizadas. Houve iniciativas isoladas de anestesistas para ajustar analgesia conforme tipo cirúrgico e orientações informais durante os plantões, mas sem formalização institucional. | J8: A análise dos resultados mostrou pequena redução na taxa de dor intensa, mas sem estabilidade. Janeiro apresentou 5% (75 casos/1.472 anestesias), Fevereiro reduziu para 4% (67 casos/1.535), Março manteve 4% (62 casos/1.533). O período apresentou instabilidade do indicador, baixa adesão protocolo e incosistencias analgésica. Houve avanços pontuais, mas sem consolidação de resultados sustentáveis. | M8: Com base nos achados, foram definidas ações estruturadas para o trimestre seguinte, incluindo a elaboração e implantação de um protocolo de avaliação e controle da dor aguda perioperatória, padronização do uso da escala EVA, capacitação das equipes de anestesia e enfermagem, e revisão dos fluxos de comunicação entre o centro cirúrgico e a SRPA. Também foi proposta a inclusão do tema nas auditorias clínicas mensais, como forma de reforçar o monitoramento contínuo do processo.
A9: FEVEREIRO | B9: Houve leve redução da incidência para 4% (67 casos/1.535 anestesias), mantendo o indicador próximo da meta. A maior parte dos pacientes, 810 (53%), permaneceu sem relato de dor, enquanto 121 (8%) apresentaram dor leve a moderada. A diminuição dos casos graves demonstra avanço discreto, porém persistem falhas na avaliação sistemática da dor e na reavaliação em SRPA, com uso não padronizado das escalas. Parte dos pacientes recebeu analgesia inadequada ao tipo de cirurgia, reforçando fragilidade no manejo analgésico de procedimentos regionais.
A10: MARÇO | B10: O mês manteve incidência de 4% (62 casos/1.533 anestesias), sem avanço expressivo no controle da dor. Do total de pacientes, 801 (52%) não apresentaram dor, enquanto 147 (10%) referiram dor leve a moderada. Embora o percentual de dor intensa tenha se mantido estável, houve relatos de subnotificação de dor leve, sugerindo que o controle e o registro ainda não estão consolidados. As auditorias demonstraram adesão parcial ao protocolo de manejo da dor aguda, porém persistem fragilidades nas intervenções analgésicas, especialmente nas anestesias regionais.
A11: MÊS | B11: Análise Critica | D11: Plan (Planejar) | G11: Do (Executar/Fazer) | J11: Check (Verificar/Checar) | M11: Act (Agir/Ajustar/Padronizar)
A12: ABRIL | B12: Observou-se melhora significativa no controle da dor, com redução da incidência para 3% (56 casos/1.622 anestesias). A maioria dos pacientes, 896 (55%), não apresentou dor, e 125 (8%) relataram dor leve a moderada, indicando melhor equilíbrio entre prevenção e tratamento analgésico. Apesar do avanço, persistem falhas pontuais na documentação das reavaliações e instabilidade no registro da intensidade da dor. As auditorias evidenciaram adesão crescente das equipes e melhor comunicação entre anestesia e SRPA, com início do uso sistemático de escalas de dor (EVA) por parte de alguns profissionais. | D12: "A partir da análise do primeiro trimestre, o planejamento concentrou-se em institucionalizar o protocolo de dor aguda, fortalecer a comunicação entre anestesia e SRPA e garantir reavaliações sistemáticas com registro em prontuário. O foco foi consolidar a uniformidade de condutas analgésicas e reduzir a variabilidade entre profissionais e turnos." | G12: "No decorrer do segundo trimestre, houve aumento da adesão ao uso da escala EVA e melhor integração entre as equipes multiprofissionais. Os anestesistas passaram a aplicar condutas analgésicas mais individualizadas, especialmente em cirurgias ortopédicas e ginecológicas, e a documentação na SRPA tornou-se mais consistente. A abertura do ambulatorio de dor e a incorporação de um anestesista especialista em dor ao serviço junto com as discussões e apresentações dos dados e auditorias começaram a gerar engajamento visível entre as equipes." | J12: "Os resultados demonstraram tendência clara de melhoria, com estabilização próxima à meta institucional: Abril apresentou 3% (56 casos/1.622 anestesias), refletindo as primeiras melhorias estruturais; Maio teve retrocesso para 6% (96 casos/1.607), possivelmente associado ao aumento de volume e complexidade cirúrgica; Junho recuperou o desempenho, voltando a 3% (51 casos/1.530). A média trimestral foi 4%, consolidando o indicador dentro da meta, porém ainda com dependência de reforço educativo e auditoria sistemática. Houve redução de variação e melhoria significativa dos resultados. Ainda que o pico de maio revele vulnerabilidade operacional, o semestre encerra com tendência de consolidação." | M12: "Com base na consolidação dos resultados, o trimestre encerrou com a formalização do protocolo institucional de dor aguda e a inclusão do tema nas auditorias clínicas periódicas. As próximas etapas envolvem monitoramento contínuo dos registros em SRPA, feedback estruturado aos anestesistas e equipes de enfermagem, e revisão periódica das condutas analgésicas por tipo de cirurgia." .
A13: MAIO | B13: O mês representou um retrocesso no desempenho, com aumento da taxa para 6% (96 casos/1.607 anestesias) — elevação de 2% em relação ao mês anterior. Entre os pacientes avaliados, 888 (55%) não apresentaram dor e 154 (10%) relataram dor leve a moderada, sugerindo desequilíbrio no controle analgésico. O aumento pode estar relacionado ao crescimento do número e da complexidade dos procedimentos, e as auditorias evidenciaram falhas na administração de analgesia e no monitoramento da dor em pacientes transferidos para UTI, além da ausência de registros de intervenções analgésicas adequadas.
A14: JUNHO | B14: O indicador retornou ao patamar de 3% (51 casos/1.530 anestesias), mostrando recuperação do controle analgésico. A maioria dos pacientes, 874 (57%), não apresentou dor, enquanto 139 (9%) relataram dor leve a moderada. Esses dados indicam maior aderência às estratégias analgésicas e melhoria na atuação das equipes de enfermagem e anestesia, com registros mais completos das escalas de dor. Contudo, a abordagem ainda carece de sistematização plena, com falhas observadas na continuidade da analgesia, especialmente em procedimentos realizados no final dos turnos.
A15: MÊS | B15: Análise Critica | D15: Plan (Planejar) | G15: Do (Executar/Fazer) | J15: Check (Verificar/Checar) | M15: Act (Agir/Ajustar/Padronizar)
A16: JULHO | B16: O mês manteve 4% (64 casos/1.781 anestesias), dentro da meta, embora com pequeno aumento em relação ao mês anterior. Entre os pacientes, 946 (53%) não apresentaram dor e 124 (7%) tiveram dor leve a moderada, o que sugere estabilidade clínica, porém necessidade de maior uniformidade na avaliação da dor. As auditorias mostraram melhor padronização das condutas e maior consistência documental, e nesse período iniciou-se a revisão do protocolo de dor, em conjunto com a equipe hospitalar e o ambulatório de dor. | D16: O planejamento do trimestre concentrou-se na revisão do protocolo institucional de dor e implantação do ambulatorio , aprimorado a partir dos resultados do semestre anterior. O objetivo foi garantir adesão integral das equipes, fortalecer a rastreabilidade dos registros e incorporar a avaliação da dor aos painéis de desempenho assistencial | G16: "Durante o período, foram realizadas reuniões multiprofissionais de revisão e validação do protocolo, alinhamentos formais sobre registro e reavaliação da dor, e implantação gradativa do novo formulário de acompanhamento em SRPA. As equipes mantiveram uso consistente da escala EVA, e o ambulatório iniciou sua atuação no tratamento dor de casos críticos e revisão de condutas analgésicas." | J16: "Os resultados confirmaram manutenção da estabilidade do indicador, melhor uniformidade das práticas e melhoria contínua na documentação. O processo analgésico apesar de ter apresentado redução de variabilidade, ainda é um desafio a ser superado." | M16: O protocolo foi revisado e descrito pelo anestesiologista especialista em dor, e atualmente segue em análise pela equipe de farmácia, com o objetivo de garantir a padronização das medicações analgésicas utilizadas. As ações para o próximo trimestre estarão concentradas na capacitação das equipes multiprofissionais e na implantação efetiva do novo protocolo institucional de dor aguda, assegurando alinhamento técnico, segurança medicamentosa e consolidação das práticas assistenciais padronizadas.
A17: AGOSTO | B17: Embora a nova versão do protocolo ainda não tenha sido implantada, o indicador apresentou 3% (58 casos/1.720 anestesias), correspondendo ao melhor resultado do semestre. A maioria dos pacientes, 917 (53%), não relatou dor, enquanto 147 (9%) apresentaram dor leve a moderada, indicando melhor controle analgésico e adesão consolidada às condutas existentes. As auditorias evidenciaram documentação consistente e intervenções adequadas, com manutenção da segurança e conforto perioperatório.
A18: SETEMBRO | B18: O mês manteve 4% (67 casos/1.823 anestesias), permanecendo dentro da meta e demonstrando controle efetivo da dor durante o período intra e pós-anestésico. A maior parte dos pacientes, 950 (52%), não apresentou dor, enquanto 110 (6%) relataram dor leve a moderada, confirmando estabilidade do manejo analgésico. As auditorias identificaram poucas falhas, relacionadas à subnotificação de dor leve e inconsistências em cirurgias de curta duração. O controle analgésico mostrou-se efetivo e seguro, sem intercorrências relevantes.

Sheet % Abreviação do jejum P.
A1: INCIDÊNCIA DE ABREVIAÇÃO DO JEJUM PROLONGADO | C1: 2025
C2: 0.32 | D2: 0.35 | E2: 0.32 | F2: 0.41 | G2: 0.38 | H2: 0.4 | I2: 0.4 | J2: 0.43 | K2: 0.42 | O2: =MEDIAN(C2:N2) -> 0.4
A3: MÊS | C3: Janeiro | D3: Fevereiro | E3: Março | F3: Abril | G3: Maio | H3: Junho | I3: Julho | J3: Agosto | K3: Setembro | L3: Outubro | M3: Novembro | N3: Dezembro | O3: Média anual
A4: N° de pacientes que receberam o suplemento para abreviação do jejum prolongado | C4: 191 | D4: 208 | E4: 221 | F4: 295 | G4: 309 | H4: 334 | I4: 293 | J4: 366 | K4: 360 | L4: 0 | M4: 0 | N4: 0 | O4: =MEDIAN(C4:N4) -> 257
A5: N° de pacientes inclusos no protocolo de abreviação de Jejum | C5: 600 | D5: 599 | E5: 689 | F5: 728 | G5: 804 | H5: 827 | I5: 728 | J5: 842 | K5: 851 | L5: 0 | M5: 0 | N5: 0 | O5: =MEDIAN(C5:N5) -> 708.5
A6: META | C6: >60%
A7: MÊS | B7: Análise Critica | D7: Plan (Planejar) | G7: Do (Executar/Fazer) | J7: Check (Verificar/Checar) | M7: Act (Agir/Ajustar/Padronizar)
A8: Janeiro | B8: O mês de janeiro apresentou uma adesão muito abaixo da meta estabelecida, com apenas 32% dos pacientes incluídos no protocolo recebendo o suplemento. A análise das auditorias revelou diversas falhas sistêmicas, especialmente nos casos de internações por urgência/emergência, onde não houve registro de avaliação pré-anestésica nem prescrição do suplemento. Houve ainda subutilização do protocolo entre pacientes eletivos, mesmo com critérios de inclusão claros. Muitos pacientes com consulta anestésica agendada não tiveram o suplemento prescrito ou administrado, e quando houve indicação, a recusa do paciente não foi devidamente registrada ou gerenciada. A ausência de integração entre a prescrição médica e a execução de enfermagem comprometeu significativamente os resultados. | D8: Durante o trimestre, a adesão manteve-se entre 32% e 35%, muito abaixo da meta institucional de >60%, indicando falhas estruturais e não apenas operacionais. As auditorias apontaram ausência de integração entre prescrição médica, execução de enfermagem e registro em prontuário eletrônico, bem como baixa rastreabilidade do processo. Principais causas identificadas: Falta de padronização do fluxo assistencial entre anestesia, enfermagem e nutrição. Prescrição ausente ou não concretizada na consulta pré-anestesica. Subutilização do protocolo em pacientes eletivos e ausência de fluxo adaptado para internações de urgências. Falta de registro formal de recusa e ausência de condutas alternativas. Falhas na avaliação glicêmica e ausência de checagem do horário de administração. Fragmentação da comunicação entre unidades (internação, anestesia e centro cirúrgico). Objetivo: Alcançar mínimo de 45% de adesão ao protocolo até o final do 2º trimestre de 2025, por meio da padronização dos fluxos, capacitação e integração dos registros. | G8: Sensibilização e capacitação técnica: início de treinamento com foco na importância fisiológica do protocolo e impacto clínico do jejum prolongado. Auditorias clínicas mensais: análise amostral de prontuários e entrevistas com equipes de anestesia e enfermagem. Discussão em comitê multidisciplinar para definição de fluxo padrão e identificação de gargalos operacionais. Elaboração de material educativo para pacientes (folder explicativo sobre suplemento e tempo de jejum). Planejamento de inclusão de campo obrigatório no prontuário eletrônico (“Paciente incluído no protocolo / motivo da não adesão”). Resultados parciais: Melhoria discreta em fevereiro, porém sem consolidação. Persistência de falhas na execução prática e no registro da administração. Identificação de resistência de parte da equipe médica e ausência de liderança formal no processo. | J8: Adesão média: 33%, sem tendência de melhoria sustentada. onformidade das auditorias do protocolo: Prescrição (52%) / Administração (48%). As ações pontuais não geraram mudança comportamental nem sistêmica. O processo ainda depende da iniciativa individual ou rotina institucionalizada. | M8: Instituir planilha de acompanhamento/registro do protocolo de abreviação do jejum na consulta pré-anestésica → Prescrição Designar anestesista para lideranças do protocolo. Definir monitoramento mensal com feedback individualizado às equipes envolvidas. Meta para o próximo ciclo (2º trimestre): Elevar adesão média para ≥40%.
A10: Fevereiro | B10: Em fevereiro, observou-se discreta melhora, embora a adesão continue insatisfatória. As falhas persistem, sobretudo na falta de registros que comprovem a inclusão formal dos pacientes no protocolo, mesmo em casos com todos os critérios atendidos. Além disso, alguns pacientes recusaram o suplemento, e essa recusa não foi sucedida por condutas alternativas nem orientações formais. Também foi identificado que a consulta pré-anestésica nem sempre resultava na prescrição do suplemento, o que evidencia a necessidade de padronização do processo e maior engajamento da equipe de anestesia. Em pacientes de urgência, não houve adaptação do fluxo assistencial, mesmo sendo tecnicamente possível.
A12: Março | B12: "O mês de março representou um retrocesso no desempenho, voltando ao mesmo nível de janeiro. O número absoluto de pacientes no protocolo aumentou, mas a proporção de adesão manteve-se baixa. As auditorias revelaram que, mesmo quando o suplemento era indicado na consulta pré-anestésica, sua prescrição não era concretizada no prontuário eletrônico. Não foram encontrados registros consistentes de horário de administração e avaliação glicêmica prévia, especialmente em pacientes diabéticos. A fragmentação das informações entre os setores de internação, anestesia e centro cirúrgico agrava o cenário, dificultando a rastreabilidade das ações e a responsabilização das falhas."
A14: MÊS | B14: Análise Critica | D14: Plan (Planejar) | G14: Do (Executar/Fazer) | J14: Check (Verificar/Checar) | M14: Act (Agir/Ajustar/Padronizar)
A15: Abril | B15: "Em abril, a adesão ao protocolo atingiu o melhor resultado do semestre, mas ainda está aquém da meta mínima aceitável. Esse leve avanço pode ter sido reflexo de ações educativas realizadas no final de março, mas não foi suficiente para consolidar uma mudança sistêmica. A análise crítica aponta que a ausência de um fluxo assistencial bem definido e automatizado é a principal barreira. Casos auditados indicam que mesmo com consulta pré-anestésica adequada, o suplemento não era prescrito, ou quando prescrito, a administração não acontecia dentro do tempo recomendado, principalmente nos primeiros horários da manhã. Isso reflete falhas na comunicação entre setores e ausência de monitoramento ativo." | D15: Durante o 2º trimestre, o indicador apresentou leve oscilação, com pico de 41% em abril, queda para 38% em maio e manutenção em 40% em junho. Apesar de avanços pontuais, a adesão ao protocolo segue aquém da meta institucional. Principais causas identificadas: Ausência de um fluxo assistencial automatizado entre prescrição, enfermagem e administração. Falta de uniformidade na avaliação pré-anestésica, com prescrições ausentes e orientações insuficientes aos pacientes. Administração fora do tempo recomendado, sobretudo em cirurgias nos primeiros horários da manhã. Baixa rastreabilidade documental, sem registro de horário ou justificativas de não adesão. Inconsistência nas ações educativas para os profissionais envolvidos. Objetivos para o proximo trimestre: Elevar a adesão média para ≥45% até setembro/2025, com padronização do fluxo de execução e monitoramento ativo. | G15: Ações implementadas ou em andamento: Reforço das ações educativas com foco na equipe de enfermagem e anestesia — incluindo revisão dos tempos de administração e benefícios clínicos da abreviação do jejum. Ampliação das auditorias clínicas conjuntas entre anestesia, nutrição e enfermagem, com ênfase em rastreabilidade documental e consistência de prescrição. Discussão com a equipe médica (anestesistas) e nutrição sobre a necessidade de revisão do fluxo de jejum em pacientes do primeiro horario da agenda da manhã, especialmente os internados. Envolvimento do setor de nutrição no acompanhamento pré-operatório de pacientes elegíveis. | J15: O periodo mostrou avanços discretos, porém sem consolidação. O processo ainda depende de iniciativa individual e não está bem institucionalizado especialmente na clareza na aplicação do protocolo em determinado grupos de pacientes ( primeiras cirurgias da manhã, pacientes internados, procedimentos especificos...). Persistem lacunas de integração entre a prescrição do suplemento e a utilização, alem de baixa conformidade nas indicações. Evidências de monitoramento: Média trimestral de adesão: 39,6%. Conformidade nas auditorias: Prescrição: 56% Administração: 51% Registro de horário: 47% Principais falhas identificadas: Falta de prescrição ou prescrição fora do tempo ideal. Recusa do paciente em tomar o suplemento por falta de conhecimento dos beneficios. Inconsistência no registro de administração no PEP dificultando o monitoramento fididigno do indicador. Ausência de responsável designado para checagem diária no bate-mapa cirurgico. | M15: Ações corretivas e padronização propostas: Implantar campo obrigatório no PEP: “Paciente incluído no protocolo de abreviação do jejum / motivo de não adesão”. Definir responsabilidade formal: anestesista como prescritor líder e participação do bate-mapa como metodo de monitorar os pacientes não incluidos no protocolo. Instituir rotina de devolutiva mensal das auditorias, com feedback individualizado aos anestesistas. Ampliar envolvimento da nutrição clínica, atuando na busca ativa de pacientes elegíveis e no acompanhamento das recusas. Meta para o próximo ciclo (3º trimestre): Atingir ≥45% de adesão ao protocolo. Consolidar registro e rastreabilidade no sistema eletrônico. Melhorar a integração entre anestesia, enfermagem e nutrição.
A17: Maio | B17: "Em maio, houve nova queda na adesão. O número de pacientes no protocolo aumentou, mas sem uma resposta proporcional na cobertura com suplemento. Persistem falhas graves, como: Prescrições feitas, mas não administradas; Administrações fora do tempo adequado; Ausência de critérios uniformes na avaliação anestésica. Os registros seguem incompletos e com baixa consistência documental, impossibilitando ações corretivas assertivas e comprometendo a rastreabilidade institucional."
A19: Junho | B19: "Em junho, a taxa de adesão permaneceu abaixo da meta, demonstrando uma estagnação nos avanços obtidos em abril. A principal fragilidade segue sendo a falta de sistematização do protocolo de ponta a ponta, da avaliação inicial à checagem pós-administração. A falta de clareza sobre quem é o responsável final pela prescrição e acompanhamento da administração gera confusão entre equipes e deixa o processo vulnerável. Apesar de alguns profissionais já aplicarem o protocolo com fidelidade, esses casos ainda são exceções, e não uma prática institucionalizada."
A21: MÊS | B21: Análise Critica | D21: Plan (Planejar) | G21: Do (Executar/Fazer) | J21: Check (Verificar/Checar) | M21: Act (Agir/Ajustar/Padronizar)
A22: Julho | B22: O mês de julho manteve baixo desempenho (40%), refletindo ausência de melhoria em relação a junho (40%) e confirmando não conformidade com a meta institucional de >60%. Dos 728 pacientes incluídos no protocolo, apenas 293 receberam o suplemento, o que indica que mais da metade dos pacientes (57%) permaneceram em jejum prolongado. As auditorias clínicas do período evidenciaram média de conformidade do protocolo de jejum e suplementação de 51%, com deficiências em prescrição (52%) e registro (48%). Persistem falhas recorrentes: ausência de prescrição no prontuário, omissão de registro da administração e comunicação ineficiente entre anestesia, paciente e enfermagem. Os registros errados/incompletos no PEP impactam confiabilidade e rastreabilidade dos dados. | D22: Durante o 3º trimestre, manteve-se o desempenho abaixo da meta institucional, com leve oscilação entre 40% e 43%, seguido de queda para 42% em setembro. A adesão ao protocolo manteve-se estável, persistindo as falhas estruturais e operacionais no processo de prescrição, execução e registro do suplemento. Principais causas identificadas: Ausência ou atraso na prescrição médica do suplemento na consulta pré anestesica ou para pacientes internados. Falhas na administração dentro do tempo recomendado, especialmente nas primeiras cirurgias do dia. Registros incompletos ou inconsistentes no prontuário eletrônico. Dificuldade de coleta consolidada do indicador nos painéis institucionais. Falta de clareza nos critérios de inclusão em casos de urgência. Resistência de parte da equipe cirurgica e falhas na comunicação entre anestesia, enfermagem e nutrição. Tempo insuficiente entre internação(gestão de acesso) e administração do suplemento. Objetivos para o ciclo: Elevar a adesão média para ≥50% até o final do próximo trimestre. Consolidar a rastreabilidade dos registros no PEP e nos painéis hospitalares. Revisar e atualizar o protocolo institucional de abreviação do jejum com base nas diretrizes atuais. Uniformizar o fluxo assistencial entre anestesia, centro cirúrgico, internação cirúrgica e nutrição. Implantar cartilha de orientação ao paciente que passa por consulta pré anestesica. | G22: Ações executadas e em andamento: Reunião multiprofissional entre anestesia, centro cirúrgico, unidade de internação cirúrgica e nutrição clínica para revisar fluxos, corrigir falhas e ampliar a adesão. Integração das análises do indicador entre hospital e serviço de anestesia, unificando a base de dados e a leitura de resultados. Atualização do folder informativo para pacientes, incluindo a orientação: “Caso não haja horário definido para cirurgia, ofertar o suplemento X horas antes.” (material em revisão final para envio ao marketing até 22/10). Revisão das diretrizes de referência (Guidelines), mantendo o jejum para sólidos em 6 horas, conforme consenso multiprofissional. Definição de um painel único para controle do indicador e centralização do fechamento dos resultados de jejum externo. Inclusão no histórico do Centro Cirúrgico da pergunta: “Paciente optou por não fazer uso do suplemento?”, visando rastreabilidade da recusa. Revisão dos tempos de tolerância ao uso dos agonistas do receptor de GLP-1, adequando o protocolo às novas evidências clínicas. Nutrição clínica intensificou busca ativa dos pacientes desde a gestão de acesso, avaliando possibilidade de antecipação da chegada para permitir o consumo dentro do tempo seguro. | J22: Resultados quantitativos: Adesão média do trimestre: 41,6% (Julho: 40%, Agosto: 43%, Setembro: 42%). Conformidade média nas auditorias: Prescrição 55% | Administração 49% | Registro 46%. Melhor documentação pré-anestésica (68%), mas falhas persistentes na execução e registro. Resultados qualitativos: A integração entre serviços e setores começou a apresentar melhor articulação de informações. O envolvimento da nutrição clínica ampliou a triagem de pacientes elegíveis, porém o tempo entre admissão e oferta do suplemento ainda é uma limitação operacional relevante. Persistem falhas de registro no PEP e dificuldades de consolidação dos dados no painel institucional, dificultando o monitoramento preciso do indicador. A análise do serviço de anestesia passou a ser integrada ao sistema hospitalar, fortalecendo a governança do processo. | M22: Ações corretivas e preventivas para o próximo ciclo: Formalizar o protocolo revisado, incorporando as diretrizes atualizadas e a padronização do tempo de jejum (6h para sólidos). Implantar o painel único de controle, centralizando o fechamento dos indicadores de jejum e suplementação. Incluir no histórico do PEP e no Centro Cirúrgico o campo obrigatório de registro: “Paciente optou por não fazer uso do suplemento” e o motivo da não adesão. Aprimorar o processo de busca ativa, avaliando estratégias para reduzir o intervalo entre internação e oferta do suplemento. Nutrição seguirá descrevendo o motivo de cada “tempo insuficiente” para análise e correção do indicador interno. Retomar as devolutivas mensais às equipes assistenciais, com foco nas unidades de maior não conformidade. Revisar fluxos e protocolos em conjunto com anestesia e enfermagem, garantindo execução dentro do tempo preconizado. Monitorar e avaliar o impacto das ações implementadas no 4º trimestre, buscando elevar a adesão média para ≥50% .
A24: Agosto | B24: Agosto apresentou pequeno avanço (43%), com 366 pacientes suplementados de um total de 842 incluídos no protocolo. Apesar da melhora marginal, o resultado segue 17 pontos percentuais abaixo da meta mínima. As auditorias indicaram melhor documentação na consulta pré-anestésica (68%), Houve melhora na documentação da consulta pré-anestésica (68%), reflexo das ações e devolutivas iniciadas no trimestre anterior. Apesar disso, persistem falhas na execução e no registro, principalmente em pacientes de urgência com tempo habil para inclusão no protocolo, cuja adesão foi inferior a 45%. A prescrição médica na consulta pré anestesica melhorou marginalmente, mas não houve correspondência na administração prática. As causas predominantes são falta de uniformidade nos critérios de inclusão dos pacientes ( horario da cirurgia, procedimentos cirurgicos, condições clinicas do paciente), A resistência de parte do corpo clínico em aderir ao protocolo e orientar o paciente quanto ao uso tem dificultando a consolidação do processo.
A26: Setembro | B26: Em setembro, observou-se uma leve queda na adesão ao protocolo, atingindo 42%, com 360 pacientes suplementados entre 851 incluídos, o que sinaliza estagnação do avanço obtido em agosto. A análise crítica dos relatórios de segurança confirma a recorrência de falhas de processo, incluindo registros de incidentes relacionados ao Protocolo de Abreviação do Jejum e ausência de documentação adequada. Os achados reforçam que o problema persiste entre a prescrição e a execução do protocolo — ou seja, o suplemento é prescrito, mas não administrado, ou é administrado fora do tempo recomendado. Além disso, permanecem falhas na indicação do suplemento, bem como dificuldades na coleta e consolidação dos dados do indicador por meio dos painéis institucionais do hospital. Persistem também inconsistências nos registros da consulta pré-anestésica e na admissão do paciente no Centro Cirúrgico. Durante o mês de setembro, foi realizada reunião conjunta entre os serviços de anestesia, centro cirúrgico, unidade de internação cirúrgica e nutrição clínica, com o objetivo de ampliar a adesão ao protocolo e corrigir falhas persistentes. Nessa ocasião, foi também integrada à análise do indicador — anteriormente conduzida de forma paralela pelo serviço de anestesia — a avaliação institucional, permitindo uma discussão conjunta dos resultados das auditorias clínicas e das dificuldades enfrentadas pelos serviços na aplicação do protocolo, tanto para pacientes com consulta pré-anestésica agendada, quanto para pacientes internados com tempo hábil de inclusão e aqueles admitidos sem inserção adequada no protocolo ou fora do tempo recomendado.
A28: MÊS | B28: Análise Critica | D28: Plan (Planejar) | G28: Do (Executar/Fazer) | J28: Check (Verificar/Checar) | M28: Act (Agir/Ajustar/Padronizar)
A29: Outubro
A31: Novembro
A33: Dezembro

Sheet Incidencia de PCR até a Alta
A1: INCIDÊNCIA DE PARADA CARDIORRESPIRATÓRIA NO PERÍODO DA INDUÇÃO ATÉ A ALTA ANESTÉSICA | C1: 2025
C2: =C4/C5 -> 0 | D2: =D4/D5 -> 0 | E2: =E4/E5 -> 0 | F2: =F4/F5 -> 0 | G2: =G4/G5 -> 0 | H2: =H4/H5 -> 0 | I2: =I4/I5 -> 0 | J2: =J4/J5 -> 0.00058139535 | K2: =K4/K5 -> 0.00054854635 | O2: =MEDIAN(C2:N2) -> 0
A3: MÊS | C3: Janeiro | D3: Fevereiro | E3: Março | F3: Abril | G3: Maio | H3: Junho | I3: Julho | J3: Agosto | K3: Setembro | L3: Outubro | M3: Novembro | N3: Dezembro | O3: Média anual
A4: Nº de pacientes submetidos a procedimentos sob anestesia/sedação com ocorrência de parada cardiorrespiratória no período da indução até a alta anestésica da SRPA ou transferência para UTI | C4: 0 | D4: 0 | E4: 0 | F4: 0 | G4: 0 | H4: 0 | I4: 0 | J4: 1 | K4: 1 | O4: =+MEDIAN(C4:N4) -> 0
A5: Nº de pacientes submetidos a procedimento sob anestesia/sedação | C5: 1472 | D5: 1535 | E5: 1533 | F5: 1622 | G5: 1607 | H5: 1530 | I5: 1781 | J5: 1720 | K5: 1823 | L5: 0 | M5: 0 | N5: 0 | O5: =MEDIAN(C5:N5) -> 1534
A6: META | C6: Meta zero / ≤1/10.000 anestesias
A7: MÊS | B7: Análise Critica | D7: Plan (Planejar) | G7: Do (Executar/Fazer) | J7: Check (Verificar/Checar) | M7: Act (Agir/Ajustar/Padronizar)
A8: Janeiro | B8: Não houve casos de PCR
A9: Fevereiro | B9: Não houve casos de PCR
A10: Março | B10: Não houve casos de PCR
A11: Abril | B11: Não houve casos de PCR
A12: Maio | B12: Não houve casos de PCR
A13: Junho | B13: Não houve casos de PCR
A14: MÊS | B14: Análise Critica | D14: Plan (Planejar) | G14: Do (Executar/Fazer) | J14: Check (Verificar/Checar) | M14: Act (Agir/Ajustar/Padronizar)
A15: Julho | B15: Não houve casos de PCR (análise de óbito)
A16: Agosto | B16: Resultado: 1 ocorrência / 1.781 anestesias Taxa: 0,00056/10.000 (dentro da meta) Descrição do evento: Durante procedimento de angioplastia complexa (técnica retrógrada por colateral epicárdica), paciente apresentou tamponamento cardíaco com evolução para parada cardiorrespiratória (PCR). A resposta da equipe foi imediata, com drenagem pericárdica de urgência, uso de suporte mecânico (BIA) e drogas vasoativas. Após manobras de reanimação, o paciente evoluiu com retorno da circulação espontânea (RCE) e foi encaminhado à UTI em estabilidade hemodinâmica. Análise crítica: Trata-se de evento adverso grave não evitável, decorrente de complicação mecânica relacionada à técnica do procedimento, e não de falha assistencial. O caso evidencia boa integração entre equipe médica, enfermagem e hemodinâmica, com resposta rápida e protocolos de emergência executados corretamente. A revisão do evento em comitê apontou aderência total aos POPs anestésicos e protocolos de suporte avançado de vida (ACLS). Conclusão: Ocorrência dentro do risco inerente à complexidade do caso. Sem falha técnica identificada. A resposta institucional foi adequada, rápida e segura.
A17: Setembro | B17: 1 ocorrência de PCR / 1.823 anestesias realizadas. Taxa: 0,00055/10.000 anestesias (dentro da meta). Descrição do evento: 1 caso: Paciente do sexo feminino, em estado séptico e instabilidade hemodinâmica grave, submetida à laparotomia de urgência. Durante a indução anestésica, apresentou duas paradas cardiorrespiratórias, revertidas após 1 ciclo de RCP em cada episódio. A paciente foi transferida para UTI, com recuperação hemodinâmica inicial e sem dano neurológico imediato. O evento foi classificado como não evitável, diretamente relacionado à condição clínica crítica da paciente. A resposta da equipe foi imediata e tecnicamente adequada, com atuação coordenada entre anestesia, enfermagem e centro cirúrgico. O caso reforça a importância da estratificação de risco anestésico em emergências, especialmente em pacientes sépticos e hipovolêmicos. Os registros e relatórios de anestesia demonstraram aderência integral ao protocolo institucional de PCR intraoperatória, sem falhas identificadas. Conclusão: Indicador dentro da meta. Evento isolado, não relacionado a falha de processo ou técnica anestésica.
A18: Outubro
A19: Novembro
A20: Dezembro

Sheet % Mudança da Tecnica Anestésica
A1: TAXA DE MUDANÇA DE TÉCNICA ANESTÉSICA | C1: 2025
C2: 0 | D2: 0 | E2: 0 | F2: 0 | G2: 0 | H2: 0 | I2: 0 | J2: 0 | K2: 0.001 | O2: =MEDIAN(C2:N2) -> 0
A3: MÊS | C3: Janeiro | D3: Fevereiro | E3: Março | F3: Abril | G3: Maio | H3: Junho | I3: Julho | J3: Agosto | K3: Setembro | L3: Outubro | M3: Novembro | N3: Dezembro | O3: Média Anual
A4: Nº de pacientes submetidos a procedimentos sob anestesia/sedação que tiveram mudança de técnica anestésica durante período intraoperatório devido a causas relativas a anestesia | C4: 0 | D4: 0 | E4: 0 | F4: 0 | G4: 0 | H4: 0 | I4: 0 | J4: 0 | K4: 1 | O4: =MEDIAN(C4:N4) -> 0
A5: Nº de pacientes submetidos a procedimentos sob anestesia/sedação | C5: 1472 | D5: 1535 | E5: 1533 | F5: 1622 | G5: 1607 | H5: 1530 | I5: 1781 | J5: 1720 | K5: 1823 | L5: 0 | M5: 0 | N5: 0 | O5: =MEDIAN(C5:N5) -> 1534
A6: META | C6: <5%
A7: MÊS | B7: Análise Critica | D7: Plan (Planejar) | G7: Do (Executar/Fazer) | J7: Check (Verificar/Checar) | M7: Act (Agir/Ajustar/Padronizar)
A8: SETEMBRO | B8: O indicador apresentou resultado estável e dentro da meta em todos os meses anteriores (0%), sem registro de outras ocorrências formais. Entretanto, durante a discussão em comitê, foi levantada a possibilidade de subnotificação de falhas anestésicas funcionais nos meses anteriores, uma vez que parte das conversões de técnica — especialmente em bloqueios parciais revertidos rapidamente — pode não ter sido registrada formalmente no sistema AxReg. Além disso, identificou-se dificuldade na busca ativa e rastreabilidade dessas ocorrências, já que nem sempre há correlação direta entre o prontuário anestésico e a notificação de evento adverso. Esse achado reforça a necessidade de fortalecer os mecanismos de vigilância ativa e integração entre os registros de anestesia, auditoria clínica e segurança do paciente. Descrição do Caso – Setembro / 2025 No dia 10/09/2025, durante procedimento ortopédico eletivo, o paciente Gabriel Enriquez Marin Perez apresentou falha de raquianestesia após punção única (L4–L5, agulha Whitacre 27G, líquor claro e refluxo adequado). Após o início da incisão, foi observada ineficácia parcial do bloqueio, com resposta motora e sensibilidade preservadas em um dos dermátomos cirúrgicos. A equipe anestésica reconheceu prontamente a falha e realizou conversão para anestesia geral balanceada com máscara laríngea nº3 e sevoflurano, mantendo estabilidade hemodinâmica e respiratória durante todo o procedimento. Classificação do incidente: Tipo: Evento adverso anestésico-cirúrgico Natureza: Falha funcional de bloqueio raquidiano Consequência: Dano leve e autolimitado (prolongamento do tempo anestésico, sem repercussões clínicas) Causa raiz: Dispersão insuficiente do anestésico local (fator intrínseco / variabilidade individual) | D8: 1- Verificar histórico do indicador e potenciais subnotificações de eventos funcionais (bloqueios parciais não registrados). 2 - Definir plano de ação para fortalecer a rastreabilidade e vigilância ativa dessas ocorrências no centro cirúrgico. | G8: Realizada investigação clínica do caso de falha raquidiana (L4–L5) durante procedimento ortopédico, com conversão imediata para anestesia geral balanceada. A equipe anestésica atuou conforme boas práticas: reconhecimento precoce, comunicação com a equipe cirúrgica, manutenção da estabilidade e registro completo no AxReg. A ocorrência foi discutida em reunião multiprofissional (anestesia, enfermagem e qualidade) para análise técnica e identificação de oportunidades de melhoria. Divulgadas orientações sobre importância do registro de falhas técnicas e funcionais, ainda que sem dano. | J8: Indicador manteve-se dentro da meta institucional, com 0,1% no mês e 0% de média anual. Revisão retrospectiva identificou baixa incidência de notificações, sugerindo possível subnotificação de eventos similares em meses anteriores. Concluiu-se que o evento foi não evitável, decorrente de variação individual na difusão do anestésico local — sem relação com erro técnico. | M8: Instituir busca ativa mensal via AxReg e painéis de anestesia para monitorar conversões não notificadas. Reforçar treinamentos sobre rastreabilidade e registro de eventos anestésicos, incluindo falhas funcionais e bloqueios parciais. Apresentar resultados e aprendizados em reunião trimestral de qualidade e segurança, consolidando cultura de transparência e melhoria contínua. Reavaliar o indicador após 90 dias para medir impacto das ações corretivas e ajustar fluxos se necessário.

Sheet % Incidência Enc. UTI
A1: ANO | C1: 2025
A2: INCIDÊNCIA DE PACIENTES ENCAMINHADOS PARA UTI SEM PLANEJAMENTO PRÉVIO COM INDICAÇÃO DECORRENTE DE EVENTOS ANESTÉSICOS | C2: =C4/C5 -> 0.00071428571 | D2: =D4/D5 -> 0 | E2: =E4/E5 -> 0.00066622252 | F2: =F4/F5 -> 0.00062460962 | G2: =G4/G5 -> 0.0023837902 | H2: =H4/H5 -> 0.0012903226 | I2: =I4/I5 -> 0.0021401819 | J2: =J4/J5 -> 0.0011267606 | K2: =K4/K5 -> 0.0010723861 | O2: =MEDIAN(C2:N2) -> 0.0010723861
A3: MÊS | C3: Janeiro | D3: Fevereiro | E3: Março | F3: Abril | G3: Maio | H3: Junho | I3: Julho | J3: Agosto | K3: Setembro | L3: Outubro | M3: Novembro | N3: Dezembro | O3: Média Anual
A4: Nº de pacientes de cirurgias eletivas sem programação de POI em UTI e que apresentaram evento anestésico necessitando transferência para essa unidade | C4: 1 | D4: 0 | E4: 1 | F4: 1 | G4: 4 | H4: 2 | I4: 4 | J4: 2 | K4: 2 | L4: 0 | M4: 0 | N4: 0 | O4: =MEDIAN(C4:N4) -> 1
A5: Nº de pacientes submetidos a procedimentos eletivos sob anestesia/sedação. | C5: 1400 | D5: 1466 | E5: 1501 | F5: 1601 | G5: 1678 | H5: 1550 | I5: 1869 | J5: 1775 | K5: 1865 | L5: 0 | M5: 0 | N5: 0 | O5: =MEDIAN(C5:N5) -> 1525.5
A6: META | C6: Meta zero / ≤0,3%
A7: MÊS | B7: Análise Critica
A8: JANEIRO | B8: Resultado mensal: 0,1% (1 evento / 1.400 procedimentos) Meta: ≤ 0,3% (meta zero) Situação: Dentro da meta Caso 1 - Ocorreu em paciente do sexo masculino, portador de hipertensão arterial sistêmica e asma, em uso de Enalapril, Diurix, Salbutamol e Fenoterol. Deu entrada no pronto-socorro em 07/01/2025 com quadro compatível com apendicite aguda perfurada e peritonite, sendo submetido à apendicectomia videolaparoscópica com drenagem subfrênica. Durante o pós-operatório imediato, apresentou hipotensão sustentada na SRPA (PAM ≈ 66 mmHg), liberado ao quarto sem reavaliação médica. Na manhã seguinte, evoluiu com sinais de sepse abdominal, sendo necessária ativação do protocolo de sepse, antibioticoterapia de amplo espectro e transferência para UTI para suporte hemodinâmico.A cultura evidenciou E. coli multirresistente, demandando ajuste antimicrobiano (meropeném). Evoluiu com melhora clínica e alta hospitalar em 15/01/2025. Houve falha no reconhecimento precoce da instabilidade hemodinâmica no pós-anestésico imediato, configurando um evento adverso evitável relacionado à transição do cuidado anestésico para o ambiente de internação. fatores contribuintes: Falha de monitoramento e comunicação entre a equipe da SRPA e o plantão no momento da alta do paciente da recuperação anestésica. Ausência de critérios objetivos de estabilidade hemodinâmica para alta da SRPA, especialmente em casos sépticos ou com foco infeccioso estabelecido. Não ADESÃO AO protocolo de reavaliação pós-operatória pelo anestesista antes da alta que poderia ter identificado a deterioração antes da necessidade de transferência à UTI.
A9: FEVEREIRO
A10: MARÇO | B10: Paciente: Edith Mantovani Fontana, 75 anos, portadora de HAS e DM, em uso contínuo de Pregabalina e Duloxetina. Procedimento: Artrodese lombar eletiva sob anestesia geral, duração de 1h30min, sem intercorrências cirúrgicas significativas. No pós-operatório imediato, ainda em sala de recuperação, apresentou episódio de mioclonia após mudança de decúbito (supina) e novas mioclonias após extubação. Evoluiu rapidamente para crise convulsiva tônico-clônica generalizada, necessitando intubação orotraqueal e ventilação mecânica para proteção das vias aéreas, sendo transferida à UTI para suporte intensivo. Os exames complementares (TC de crânio, EEG seriados e exames laboratoriais) descartaram causas estruturais e evidenciaram paroxismos epileptiformes frontais e temporais, compatíveis com encefalopatia medicamentosa e/ou metabólica. O quadro evoluiu com melhora progressiva, permitindo extubação no 3º dia de UTI e alta hospitalar em 24/03/2025, em boas condições clínicas. Evento anestésico-neurológico agudo, de caráter não previsível, porém necessitando de suporte intensivo imediato. Fatores contribuintes identificados: Susceptibilidade neurológica prévia: uso crônico de Pregabalina e Duloxetina, que podem baixar o limiar convulsivo e interagir com anestésicos e analgésicos opioides. Potencial interação medicamentosa: associação entre anestesia geral, agentes sedativos e antidepressivos serotoninérgicos, favorecendo encefalopatia tóxica e crises mioclônicas. Distúrbio metabólico leve no intra e pós-operatório inicial, com hipocalemia (K 2,7) e hipofosfatemia, ambos reconhecidos como precipitantes de atividade epiléptica. Ausência de antecedentes epilépticos conhecidos, configurando evento de caráter idiossincrático, não prevenível no planejamento anestésico habitual.
A11: ABRIL | B11: Resultado mensal: 0,1% (1 evento / 1.601 procedimentos) Meta: ≤ 0,3% (meta zero) Situação: Dentro da meta Paciente: Vitório Ansolin, 71 anos, com histórico de adenocarcinoma gástrico em tratamento quimioterápico paliativo (FOLFOX + Nivolumabe), portador de port-a-cath implantado em 14/02/2025, e múltiplas comorbidades (HAS, DM2, estenose aórtica pós-TAVI, FA paroxística). Em 31/03, foi avaliado por infectologia devido a hiperemia, calor e dor no sítio do port-a-cath direito, associadas à elevação de PCR (236 mg/L) e aumento de creatinina (1,9 mg/dL). O ultrassom mostrou coleção subclávia sugestiva de abscesso peri-cateter, com indicação de retirada do dispositivo. Em 01/04, foi realizada remoção do port-a-cath direito e colocação de novo cateter à esquerda, sob anestesia local e sem sedação. Durante a recuperação anestésica (SRPA), o paciente evoluiu com taquicardia, tremores e agitação psicomotora, seguidos de hipotensão persistente (≈90x60 mmHg) e taquicardia (105 bpm), caracterizando choque séptico pós-procedimento. Foi administrado vasopressor e, diante da instabilidade, realizada transferência imediata para UTI, onde recebeu suporte hemodinâmico, antibioticoterapia de amplo espectro (cefepime + daptomicina) e medidas de controle da infecção. A cultura da ponta do cateter confirmou infecção de corrente sanguínea associada ao port-a-cath (ICSAC). Evoluiu com melhora clínica após terapia intensiva e ajuste antimicrobiano. Infecção pré-existente do port-a-cath com sinais flogísticos evidentes antes da intervenção, mas sem bacteremia confirmada. Paciente oncológico imunossuprimido, neutropênico e com múltiplas comorbidades cardiovasculares, aumentando o risco de descompensação hemodinâmica. Provável liberação bacteriana sistêmica durante a manipulação e retirada do dispositivo infectado, precipitando choque séptico intra/SRPA. Ausência de planejamento prévio para suporte intensivo imediato, apesar do alto risco de instabilidade, o que caracteriza transferência não planejada à UTI. O evento representa uma intercorrência infecciosa grave com descompensação hemodinâmica imediata no pós-procedimento, configurando encaminhamento não planejado à UTI. Embora previsível em termos de risco (dado o contexto séptico e oncológico), o choque séptico instalou-se abruptamente, justificando o acionamento emergencial.
